{
  "id": "MAL-2024-4870",
  "summary": "Malicious code in capmonsterclouddlient (PyPI)",
  "details": "\n---\n_-= Per source details. Do not edit below this line.=-_\n",
  "aliases": [
    "SNYK-PYTHON-CAPMONSTERCLOUDDLIENT-6513451"
  ],
  "modified": "2024-06-28T03:14:48.712390Z",
  "published": "2024-06-25T13:33:14Z",
  "database_specific": {
    "malicious-packages-origins": [
      {
        "modified_time": "2024-06-25T13:33:14Z",
        "import_time": "2024-06-28T02:48:27.663199923Z",
        "versions": [
          "1.0.0"
        ],
        "id": "RLMA-2024-03650",
        "source": "reversing-labs",
        "sha256": "614eee78efd28ec7aca9e2e3d6df11de2ba7033b578495286c948b6a8d8b2dd5"
      }
    ]
  },
  "references": [
    {
      "type": "ADVISORY",
      "url": "https://security.snyk.io/vuln/SNYK-PYTHON-CAPMONSTERCLOUDDLIENT-6513451"
    },
    {
      "type": "ARTICLE",
      "url": "https://medium.com/checkmarx-security/pypi-is-under-attack-project-creation-and-user-registration-suspended-heres-the-details-c3b6291d4579"
    }
  ],
  "affected": [
    {
      "package": {
        "name": "capmonsterclouddlient",
        "ecosystem": "PyPI",
        "purl": "pkg:pypi/capmonsterclouddlient"
      },
      "versions": [
        "1.0.0"
      ],
      "database_specific": {
        "source": "https://github.com/ossf/malicious-packages/blob/main/osv/malicious/pypi/capmonsterclouddlient/MAL-2024-4870.json"
      }
    }
  ],
  "schema_version": "1.6.0",
  "credits": [
    {
      "name": "ReversingLabs",
      "contact": [
        "https://www.reversinglabs.com"
      ],
      "type": "FINDER"
    }
  ]
}