{
  "id": "MAL-2024-5204",
  "summary": "Malicious code in hnuhfyzumkmo (PyPI)",
  "details": "\n---\n_-= Per source details. Do not edit below this line.=-_\n",
  "aliases": [
    "SNYK-PYTHON-HNUHFYZUMKMO-6483330"
  ],
  "modified": "2024-06-28T03:14:54.182086Z",
  "published": "2024-06-25T13:35:57Z",
  "database_specific": {
    "malicious-packages-origins": [
      {
        "modified_time": "2024-06-25T13:35:57Z",
        "import_time": "2024-06-28T02:49:06.523046206Z",
        "versions": [
          "0.3.2"
        ],
        "id": "RLMA-2024-03986",
        "source": "reversing-labs",
        "sha256": "c8f733eadaea75fd430db201882aa770ebe0f88cc7561b421cb72f5e9333976a"
      }
    ]
  },
  "references": [
    {
      "type": "ADVISORY",
      "url": "https://security.snyk.io/vuln/SNYK-PYTHON-HNUHFYZUMKMO-6483330"
    },
    {
      "type": "ARTICLE",
      "url": "https://medium.com/checkmarx-security/over-170k-users-affected-by-attack-using-fake-python-infrastructure-05a04b7e058a"
    }
  ],
  "affected": [
    {
      "package": {
        "name": "hnuhfyzumkmo",
        "ecosystem": "PyPI",
        "purl": "pkg:pypi/hnuhfyzumkmo"
      },
      "versions": [
        "0.3.2"
      ],
      "database_specific": {
        "source": "https://github.com/ossf/malicious-packages/blob/main/osv/malicious/pypi/hnuhfyzumkmo/MAL-2024-5204.json"
      }
    }
  ],
  "schema_version": "1.6.0",
  "credits": [
    {
      "name": "ReversingLabs",
      "contact": [
        "https://www.reversinglabs.com"
      ],
      "type": "FINDER"
    }
  ]
}