{
  "id": "MAL-2024-5474",
  "summary": "Malicious code in pilloo (PyPI)",
  "details": "\n---\n_-= Per source details. Do not edit below this line.=-_\n",
  "aliases": [
    "SNYK-PYTHON-PILLOO-6513446"
  ],
  "modified": "2024-06-28T03:14:57.430521Z",
  "published": "2024-06-25T13:38:07Z",
  "database_specific": {
    "malicious-packages-origins": [
      {
        "modified_time": "2024-06-25T13:38:07Z",
        "import_time": "2024-06-28T02:49:38.660875851Z",
        "versions": [
          "1.0.0"
        ],
        "id": "RLMA-2024-04256",
        "source": "reversing-labs",
        "sha256": "6e62d515a26be3267bd069a15acd539381606019c20980d17a65a1f70be18196"
      }
    ]
  },
  "references": [
    {
      "type": "ARTICLE",
      "url": "https://medium.com/checkmarx-security/pypi-is-under-attack-project-creation-and-user-registration-suspended-heres-the-details-c3b6291d4579"
    },
    {
      "type": "ADVISORY",
      "url": "https://security.snyk.io/vuln/SNYK-PYTHON-PILLOO-6513446"
    }
  ],
  "affected": [
    {
      "package": {
        "name": "pilloo",
        "ecosystem": "PyPI",
        "purl": "pkg:pypi/pilloo"
      },
      "versions": [
        "1.0.0"
      ],
      "database_specific": {
        "source": "https://github.com/ossf/malicious-packages/blob/main/osv/malicious/pypi/pilloo/MAL-2024-5474.json"
      }
    }
  ],
  "schema_version": "1.6.0",
  "credits": [
    {
      "name": "ReversingLabs",
      "contact": [
        "https://www.reversinglabs.com"
      ],
      "type": "FINDER"
    }
  ]
}