{
  "id": "MAL-2024-5978",
  "summary": "Malicious code in seleiumm (PyPI)",
  "details": "\n---\n_-= Per source details. Do not edit below this line.=-_\n",
  "aliases": [
    "SNYK-PYTHON-SELEIUMM-6513583"
  ],
  "modified": "2024-06-28T03:15:15.917815Z",
  "published": "2024-06-25T13:42:20Z",
  "database_specific": {
    "malicious-packages-origins": [
      {
        "modified_time": "2024-06-25T13:42:20Z",
        "import_time": "2024-06-28T02:50:41.102407242Z",
        "versions": [
          "1.0.0"
        ],
        "id": "RLMA-2024-04779",
        "source": "reversing-labs",
        "sha256": "9767bdb77cd5de4aa7f673c0d3ae6fca1838afdac4d71249a65655a0848d41bf"
      }
    ]
  },
  "references": [
    {
      "type": "ADVISORY",
      "url": "https://security.snyk.io/vuln/SNYK-PYTHON-SELEIUMM-6513583"
    },
    {
      "type": "ARTICLE",
      "url": "https://medium.com/checkmarx-security/pypi-is-under-attack-project-creation-and-user-registration-suspended-heres-the-details-c3b6291d4579"
    }
  ],
  "affected": [
    {
      "package": {
        "name": "seleiumm",
        "ecosystem": "PyPI",
        "purl": "pkg:pypi/seleiumm"
      },
      "versions": [
        "1.0.0"
      ],
      "database_specific": {
        "source": "https://github.com/ossf/malicious-packages/blob/main/osv/malicious/pypi/seleiumm/MAL-2024-5978.json"
      }
    }
  ],
  "schema_version": "1.6.0",
  "credits": [
    {
      "name": "ReversingLabs",
      "contact": [
        "https://www.reversinglabs.com"
      ],
      "type": "FINDER"
    }
  ]
}