{
  "id": "MAL-2024-4852",
  "summary": "Malicious code in capmonstercloudclenit (PyPI)",
  "details": "\n---\n_-= Per source details. Do not edit below this line.=-_\n",
  "aliases": [
    "SNYK-PYTHON-CAPMONSTERCLOUDCLENIT-6513279"
  ],
  "modified": "2024-06-28T03:27:23.498642Z",
  "published": "2024-06-25T13:33:05Z",
  "database_specific": {
    "malicious-packages-origins": [
      {
        "modified_time": "2024-06-25T13:33:05Z",
        "import_time": "2024-06-28T02:48:25.674138596Z",
        "versions": [
          "1.0.0"
        ],
        "id": "RLMA-2024-03632",
        "source": "reversing-labs",
        "sha256": "ba9f9a9c016abfca75505beb1e1eb2a5a6316269574d29ac502a409d4db17e14"
      }
    ]
  },
  "references": [
    {
      "type": "ADVISORY",
      "url": "https://security.snyk.io/vuln/SNYK-PYTHON-CAPMONSTERCLOUDCLENIT-6513279"
    },
    {
      "type": "ARTICLE",
      "url": "https://medium.com/checkmarx-security/pypi-is-under-attack-project-creation-and-user-registration-suspended-heres-the-details-c3b6291d4579"
    }
  ],
  "affected": [
    {
      "package": {
        "name": "capmonstercloudclenit",
        "ecosystem": "PyPI",
        "purl": "pkg:pypi/capmonstercloudclenit"
      },
      "versions": [
        "1.0.0"
      ],
      "database_specific": {
        "source": "https://github.com/ossf/malicious-packages/blob/main/osv/malicious/pypi/capmonstercloudclenit/MAL-2024-4852.json"
      }
    }
  ],
  "schema_version": "1.6.0",
  "credits": [
    {
      "name": "ReversingLabs",
      "contact": [
        "https://www.reversinglabs.com"
      ],
      "type": "FINDER"
    }
  ]
}