{
  "id": "MAL-2024-5575",
  "summary": "Malicious code in pullow (PyPI)",
  "details": "\n---\n_-= Per source details. Do not edit below this line.=-_\n",
  "aliases": [
    "SNYK-PYTHON-PULLOW-6513250"
  ],
  "modified": "2024-06-28T03:15:01.482919Z",
  "published": "2024-06-25T13:38:55Z",
  "database_specific": {
    "malicious-packages-origins": [
      {
        "modified_time": "2024-06-25T13:38:55Z",
        "import_time": "2024-06-28T02:49:50.847937873Z",
        "versions": [
          "1.0.0"
        ],
        "id": "RLMA-2024-04357",
        "source": "reversing-labs",
        "sha256": "c16374c5fae8ea28a9fbb294154e94bed0af7f02e0972f937dafa66dc17e58ec"
      }
    ]
  },
  "references": [
    {
      "type": "ARTICLE",
      "url": "https://medium.com/checkmarx-security/pypi-is-under-attack-project-creation-and-user-registration-suspended-heres-the-details-c3b6291d4579"
    },
    {
      "type": "ADVISORY",
      "url": "https://security.snyk.io/vuln/SNYK-PYTHON-PULLOW-6513250"
    }
  ],
  "affected": [
    {
      "package": {
        "name": "pullow",
        "ecosystem": "PyPI",
        "purl": "pkg:pypi/pullow"
      },
      "versions": [
        "1.0.0"
      ],
      "database_specific": {
        "source": "https://github.com/ossf/malicious-packages/blob/main/osv/malicious/pypi/pullow/MAL-2024-5575.json"
      }
    }
  ],
  "schema_version": "1.6.0",
  "credits": [
    {
      "name": "ReversingLabs",
      "contact": [
        "https://www.reversinglabs.com"
      ],
      "type": "FINDER"
    }
  ]
}