{
  "id": "MAL-2024-4857",
  "summary": "Malicious code in capmonstercloudclien (PyPI)",
  "details": "\n---\n_-= Per source details. Do not edit below this line.=-_\n",
  "aliases": [
    "SNYK-PYTHON-CAPMONSTERCLOUDCLIEN-6513716"
  ],
  "modified": "2024-06-28T03:14:47.916107Z",
  "published": "2024-06-25T13:33:08Z",
  "database_specific": {
    "malicious-packages-origins": [
      {
        "modified_time": "2024-06-25T13:33:08Z",
        "import_time": "2024-06-28T02:48:26.270570321Z",
        "versions": [
          "1.0.0"
        ],
        "id": "RLMA-2024-03637",
        "source": "reversing-labs",
        "sha256": "e38c4dda675a6ab326d1a6842d39275b0c43502442e49c3a587937f39b4044f8"
      }
    ]
  },
  "references": [
    {
      "type": "ADVISORY",
      "url": "https://security.snyk.io/vuln/SNYK-PYTHON-CAPMONSTERCLOUDCLIEN-6513716"
    },
    {
      "type": "ARTICLE",
      "url": "https://medium.com/checkmarx-security/pypi-is-under-attack-project-creation-and-user-registration-suspended-heres-the-details-c3b6291d4579"
    }
  ],
  "affected": [
    {
      "package": {
        "name": "capmonstercloudclien",
        "ecosystem": "PyPI",
        "purl": "pkg:pypi/capmonstercloudclien"
      },
      "versions": [
        "1.0.0"
      ],
      "database_specific": {
        "source": "https://github.com/ossf/malicious-packages/blob/main/osv/malicious/pypi/capmonstercloudclien/MAL-2024-4857.json"
      }
    }
  ],
  "schema_version": "1.6.0",
  "credits": [
    {
      "name": "ReversingLabs",
      "contact": [
        "https://www.reversinglabs.com"
      ],
      "type": "FINDER"
    }
  ]
}