{
  "id": "MAL-2024-5623",
  "summary": "Malicious code in py-cozd (PyPI)",
  "details": "\n---\n_-= Per source details. Do not edit below this line.=-_\n",
  "aliases": [
    "SNYK-PYTHON-PYCOZD-6513185"
  ],
  "modified": "2024-06-28T03:27:23.985149Z",
  "published": "2024-06-25T13:39:18Z",
  "database_specific": {
    "malicious-packages-origins": [
      {
        "modified_time": "2024-06-25T13:39:18Z",
        "import_time": "2024-06-28T02:49:56.418447289Z",
        "versions": [
          "1.0.0"
        ],
        "id": "RLMA-2024-04405",
        "source": "reversing-labs",
        "sha256": "c3db3eb14fae48a3ab2940bcc140d9856beea1f9bd69b5be648245303dd10a41"
      }
    ]
  },
  "references": [
    {
      "type": "ARTICLE",
      "url": "https://medium.com/checkmarx-security/pypi-is-under-attack-project-creation-and-user-registration-suspended-heres-the-details-c3b6291d4579"
    },
    {
      "type": "ADVISORY",
      "url": "https://security.snyk.io/vuln/SNYK-PYTHON-PYCOZD-6513185"
    }
  ],
  "affected": [
    {
      "package": {
        "name": "py-cozd",
        "ecosystem": "PyPI",
        "purl": "pkg:pypi/py-cozd"
      },
      "versions": [
        "1.0.0"
      ],
      "database_specific": {
        "source": "https://github.com/ossf/malicious-packages/blob/main/osv/malicious/pypi/py-cozd/MAL-2024-5623.json"
      }
    }
  ],
  "schema_version": "1.6.0",
  "credits": [
    {
      "name": "ReversingLabs",
      "contact": [
        "https://www.reversinglabs.com"
      ],
      "type": "FINDER"
    }
  ]
}